<?xml version="1.0"?>

<robot xmlns:sensor="http://playerstage.sourceforge.net/gazebo/xmlschema/#sensor"
       xmlns:controller="http://playerstage.sourceforge.net/gazebo/xmlschema/#controller"
       xmlns:interface="http://playerstage.sourceforge.net/gazebo/xmlschema/#interface"
       xmlns:xacro="http://ros.org/wiki/xacro">

<xacro:macro name="rr_linear_axis" params="   parent 
											  child 
											  origin_x:=0
											  origin_y:=0
											  origin_z:=0
											  origin_R:=0
											  origin_P:=0
										      origin_Y:=0
										      effort 
											  lower 
											  upper 
											  velocity
											  axis
											  ros_control:=false
											  ros_control_actuator:='motor1'
											  ros_control_effort:=false
											  ros_control_velocity:=false
											  ros_control_position:=false
											  ros_control_reduction:=1
											  joint_name=''
											  ">
	
	<xacro:if value="${joint_name == ''}">
		 <xacro:property name="joint_name_in" value="joint_linear_${parent}_${child}" />
	</xacro:if>									  	
	<xacro:unless value="${joint_name == ''}">
		 <xacro:property name="joint_name_in" value="${joint_name}" />
	</xacro:unless>												  	
											  	
   	  <joint name="${joint_name_in}" type="prismatic">
			<parent link="${parent}" />
			<child  link="${child}" />
			<origin xyz="${origin_x} ${origin_y} ${origin_z}" rpy="${origin_R} ${origin_P} ${origin_Y}" />	
		    <limit effort="${effort}" lower="${lower}" upper="${upper}" velocity="${velocity}"/>
      		
      		
			<xacro:if value="${axis == 'x'}">
				<axis xyz="1 0 0"/>
			</xacro:if>
			<xacro:if value="${axis == 'y'}">
				<axis xyz="0 1 0"/>
			</xacro:if>
			<xacro:if value="${axis == 'z'}">
				<axis xyz="0 0 1"/>
			</xacro:if>
			     			
      </joint>  
      
     <xacro:if value="${ros_control}">
     	
		<xacro:rr_roscontrol_simple_joint_transmission 
			joint="${joint_name_in}" 
			actuator="${ros_control_actuator}"			
			effort="${ros_control_effort}"			
			velocity="${ros_control_velocity}"			
			position="${ros_control_position}"			
		  	reduction="${ros_control_reduction}" />
     </xacro:if>
      
</xacro:macro>



</robot>
